[2024-07-11T15:19:11.776+0700] {local_task_job_runner.py:120} INFO - ::group::Pre task execution logs
[2024-07-11T15:19:11.830+0700] {taskinstance.py:2076} INFO - Dependencies all met for dep_context=non-requeueable deps ti=<TaskInstance: update_allogistic.run_notebook scheduled__2024-07-11T07:00:00+00:00 [queued]>
[2024-07-11T15:19:11.872+0700] {taskinstance.py:2076} INFO - Dependencies all met for dep_context=requeueable deps ti=<TaskInstance: update_allogistic.run_notebook scheduled__2024-07-11T07:00:00+00:00 [queued]>
[2024-07-11T15:19:11.876+0700] {taskinstance.py:2306} INFO - Starting attempt 2 of 2
[2024-07-11T15:19:11.994+0700] {taskinstance.py:2330} INFO - Executing <Task(PythonOperator): run_notebook> on 2024-07-11 07:00:00+00:00
[2024-07-11T15:19:12.006+0700] {standard_task_runner.py:63} INFO - Started process 42786 to run task
[2024-07-11T15:19:12.011+0700] {standard_task_runner.py:90} INFO - Running: ['airflow', 'tasks', 'run', 'update_allogistic', 'run_notebook', 'scheduled__2024-07-11T07:00:00+00:00', '--job-id', '10', '--raw', '--subdir', 'DAGS_FOLDER/allogistic.py', '--cfg-path', '/tmp/tmp8ewgft0z']
[2024-07-11T15:19:12.019+0700] {standard_task_runner.py:91} INFO - Job 10: Subtask run_notebook
[2024-07-11T15:19:12.290+0700] {task_command.py:426} INFO - Running <TaskInstance: update_allogistic.run_notebook scheduled__2024-07-11T07:00:00+00:00 [running]> on host LWIN-ID-OCT22-0115.
[2024-07-11T15:19:12.694+0700] {taskinstance.py:2648} INFO - Exporting env vars: AIRFLOW_CTX_DAG_OWNER='airflow' AIRFLOW_CTX_DAG_ID='update_allogistic' AIRFLOW_CTX_TASK_ID='run_notebook' AIRFLOW_CTX_EXECUTION_DATE='2024-07-11T07:00:00+00:00' AIRFLOW_CTX_TRY_NUMBER='2' AIRFLOW_CTX_DAG_RUN_ID='scheduled__2024-07-11T07:00:00+00:00'
[2024-07-11T15:19:12.700+0700] {taskinstance.py:430} INFO - ::endgroup::
[2024-07-11T15:19:12.704+0700] {taskinstance.py:441} INFO - ::group::Post task execution logs
[2024-07-11T15:19:12.709+0700] {taskinstance.py:2905} ERROR - Task failed with exception
Traceback (most recent call last):
  File "/mnt/c/Users/Erland/Documents/GitHub/airflow/py_env/lib/python3.10/site-packages/airflow/models/taskinstance.py", line 465, in _execute_task
    result = _execute_callable(context=context, **execute_callable_kwargs)
  File "/mnt/c/Users/Erland/Documents/GitHub/airflow/py_env/lib/python3.10/site-packages/airflow/models/taskinstance.py", line 432, in _execute_callable
    return execute_callable(context=context, **execute_callable_kwargs)
  File "/mnt/c/Users/Erland/Documents/GitHub/airflow/py_env/lib/python3.10/site-packages/airflow/models/baseoperator.py", line 401, in wrapper
    return func(self, *args, **kwargs)
  File "/mnt/c/Users/Erland/Documents/GitHub/airflow/py_env/lib/python3.10/site-packages/airflow/operators/python.py", line 235, in execute
    return_value = self.execute_callable()
  File "/mnt/c/Users/Erland/Documents/GitHub/airflow/py_env/lib/python3.10/site-packages/airflow/operators/python.py", line 252, in execute_callable
    return self.python_callable(*self.op_args, **self.op_kwargs)
  File "/mnt/c/Users/Erland/Documents/GitHub/airflow/dags/allogistic.py", line 33, in run_notebook
    pm.execute_notebook(
TypeError: execute_notebook() missing 1 required positional argument: 'output_path'
[2024-07-11T15:19:12.835+0700] {taskinstance.py:1206} INFO - Marking task as FAILED. dag_id=update_allogistic, task_id=run_notebook, run_id=scheduled__2024-07-11T07:00:00+00:00, execution_date=20240711T070000, start_date=20240711T081911, end_date=20240711T081912
[2024-07-11T15:19:12.960+0700] {standard_task_runner.py:110} ERROR - Failed to execute job 10 for task run_notebook (execute_notebook() missing 1 required positional argument: 'output_path'; 42786)
[2024-07-11T15:19:12.998+0700] {local_task_job_runner.py:240} INFO - Task exited with return code 1
[2024-07-11T15:19:13.057+0700] {taskinstance.py:3503} INFO - 0 downstream tasks scheduled from follow-on schedule check
[2024-07-11T15:19:13.065+0700] {local_task_job_runner.py:222} INFO - ::endgroup::
